Traceback (most recent call last):
  File "/opt/anaconda3/envs/jupyter-book-py311/lib/python3.11/site-packages/jupyter_cache/executors/utils.py", line 58, in single_nb_execution
    executenb(
  File "/opt/anaconda3/envs/jupyter-book-py311/lib/python3.11/site-packages/nbclient/client.py", line 1305, in execute
    return NotebookClient(nb=nb, resources=resources, km=km, **kwargs).execute()
           ^^^^^^^^^^^^^^^^^^^^^^^^^^^^^^^^^^^^^^^^^^^^^^^^^^^^^^^^^^^^^^^^^^^^^
  File "/opt/anaconda3/envs/jupyter-book-py311/lib/python3.11/site-packages/jupyter_core/utils/__init__.py", line 173, in wrapped
    return loop.run_until_complete(inner)
           ^^^^^^^^^^^^^^^^^^^^^^^^^^^^^^
  File "/opt/anaconda3/envs/jupyter-book-py311/lib/python3.11/asyncio/base_events.py", line 654, in run_until_complete
    return future.result()
           ^^^^^^^^^^^^^^^
  File "/opt/anaconda3/envs/jupyter-book-py311/lib/python3.11/site-packages/nbclient/client.py", line 705, in async_execute
    await self.async_execute_cell(
  File "/opt/anaconda3/envs/jupyter-book-py311/lib/python3.11/site-packages/nbclient/client.py", line 1058, in async_execute_cell
    await self._check_raise_for_error(cell, cell_index, exec_reply)
  File "/opt/anaconda3/envs/jupyter-book-py311/lib/python3.11/site-packages/nbclient/client.py", line 914, in _check_raise_for_error
    raise CellExecutionError.from_cell_and_msg(cell, exec_reply_content)
nbclient.exceptions.CellExecutionError: An error occurred while executing the following cell:
------------------
# foliumパッケージを使う
import folium

#lat1,lon1 = siracusa.latlng
#lat2,lon2 = selinunte.latlng
lat1,lon1 = siracusa
lat2,lon2 = selinunte

# 地図を作る
fmap = folium.Map(location=siracusa,zoom_start=6)
#fmap = folium.Map(location=siracusa.latlng,zoom_start=6)

# マーカープロット
folium.Marker(location=[lat1,lon1],
              icon=folium.Icon(color='black')
             ).add_to(fmap)
folium.Marker(location=[lat2,lon2],icon=folium.Icon(color='blue')
             ).add_to(fmap)
fmap # 表示する
------------------


[0;31m---------------------------------------------------------------------------[0m
[0;31mTypeError[0m                                 Traceback (most recent call last)
Cell [0;32mIn[2], line 6[0m
[1;32m      2[0m [38;5;28;01mimport[39;00m [38;5;21;01mfolium[39;00m
[1;32m      4[0m [38;5;66;03m#lat1,lon1 = siracusa.latlng[39;00m
[1;32m      5[0m [38;5;66;03m#lat2,lon2 = selinunte.latlng[39;00m
[0;32m----> 6[0m lat1,lon1 [38;5;241m=[39m siracusa
[1;32m      7[0m lat2,lon2 [38;5;241m=[39m selinunte
[1;32m      9[0m [38;5;66;03m# 地図を作る[39;00m

[0;31mTypeError[0m: cannot unpack non-iterable NoneType object

